Workbook

Sheet 老干部
A1: 老干部党支部2026年度党员学习统计表
A2: 填报单位：
A3: 序号 | B3: 姓名 | C3: 入党时间 | D3: 参加培训时间 | E3: 培训方式及内容 | F3: 培训时长（45分钟=1学时） | G3: 总学时
A4: 1 | B4: 贾桂芝 | C4: =VLOOKUP(B4,[1]导出名册!$A$1:$H$65536,8,FALSE) -> 1995-07-01 | D4: 2026.01.17 | E4: 参加二十届四中全会精神教育集中培训《“十五五”时期经济社会发展的指导思想、重大原则和根本保证》《“十五五”时期经济社会发展的重大战略任务》，围绕深入贯彻落实党的二十届四中全会精神及省委十三届八次全会部署、深入贯彻落实市委十四届八次全会及县委十七届九次全会部署开展研讨 | F4: 6 | G4: =SUM(F4:F9) -> 18.5
D5: 2026.02.06 | E5: 参加2026年第一期“龙江先锋网”省级直播授课培训《提升基层安全应急能力 助力地方高质量发展》 | F5: 2.5
D6: 2026.02.26 | E6: 参加2026年第二期“龙江先锋网”省级直播授课培训《全面贯彻省委经济工作会议精神 确保实现‘十五五’开好局起好步》 | F6: 2.5
D7: 2026.03.18 | E7: 参加2026年第一期“三江党旗红 党员在行动”直播授课培训《佳木斯市大垄密植增产技术措施》《狮头鹅和湖羊养殖实操精要与疫病防控》 | F7: 2.5
D8: 2026.03.25 | E8: 参加2026年第三期“龙江先锋网”省级直播授课培训《树立和践行正确政绩观》《大豆产业提质增效》 | F8: 2.5
D9: 2026.04.15 | E9: 参加2026年第五期“龙江先锋网”省级直播授课培训《深入学习贯彻习近平法治思想，以全民普法夯实基层治理法治根基》 | F9: 2.5
A10: 2 | B10: 金贞淑 | C10: =VLOOKUP(B10,[1]导出名册!$A$1:$H$65536,8,FALSE) -> 1993-03-01 | D10: 2026.01.17 | E10: 参加二十届四中全会精神教育集中培训《“十五五”时期经济社会发展的指导思想、重大原则和根本保证》《“十五五”时期经济社会发展的重大战略任务》，围绕深入贯彻落实党的二十届四中全会精神及省委十三届八次全会部署、深入贯彻落实市委十四届八次全会及县委十七届九次全会部署开展研讨 | F10: 6 | G10: =SUM(F10:F15) -> 18.5
D11: 2026.02.06 | E11: 参加2026年第一期“龙江先锋网”省级直播授课培训《提升基层安全应急能力 助力地方高质量发展》 | F11: 2.5
D12: 2026.02.26 | E12: 参加2026年第二期“龙江先锋网”省级直播授课培训《全面贯彻省委经济工作会议精神 确保实现‘十五五’开好局起好步》 | F12: 2.5
D13: 2026.03.18 | E13: 参加2026年第一期“三江党旗红 党员在行动”直播授课培训《佳木斯市大垄密植增产技术措施》《狮头鹅和湖羊养殖实操精要与疫病防控》 | F13: 2.5
D14: 2026.03.25 | E14: 参加2026年第三期“龙江先锋网”省级直播授课培训《树立和践行正确政绩观》《大豆产业提质增效》 | F14: 2.5
D15: 2026.04.15 | E15: 参加2026年第五期“龙江先锋网”省级直播授课培训《深入学习贯彻习近平法治思想，以全民普法夯实基层治理法治根基》 | F15: 2.5
A16: 3 | B16: 张士田 | C16: =VLOOKUP(B16,[1]导出名册!$A$1:$H$65536,8,FALSE) -> 1975-06-15 | D16: 2026.01.17 | E16: 参加二十届四中全会精神教育集中培训《“十五五”时期经济社会发展的指导思想、重大原则和根本保证》《“十五五”时期经济社会发展的重大战略任务》，围绕深入贯彻落实党的二十届四中全会精神及省委十三届八次全会部署、深入贯彻落实市委十四届八次全会及县委十七届九次全会部署开展研讨 | F16: 6 | G16: =SUM(F16:F21) -> 18.5
D17: 2026.02.06 | E17: 参加2026年第一期“龙江先锋网”省级直播授课培训《提升基层安全应急能力 助力地方高质量发展》 | F17: 2.5
D18: 2026.02.26 | E18: 参加2026年第二期“龙江先锋网”省级直播授课培训《全面贯彻省委经济工作会议精神 确保实现‘十五五’开好局起好步》 | F18: 2.5
D19: 2026.03.18 | E19: 参加2026年第一期“三江党旗红 党员在行动”直播授课培训《佳木斯市大垄密植增产技术措施》《狮头鹅和湖羊养殖实操精要与疫病防控》 | F19: 2.5
D20: 2026.03.25 | E20: 参加2026年第三期“龙江先锋网”省级直播授课培训《树立和践行正确政绩观》《大豆产业提质增效》 | F20: 2.5
D21: 2026.04.15 | E21: 参加2026年第五期“龙江先锋网”省级直播授课培训《深入学习贯彻习近平法治思想，以全民普法夯实基层治理法治根基》 | F21: 2.5
A22: 4 | B22: 蔺刚 | C22: =VLOOKUP(B22,[1]导出名册!$A$1:$H$65536,8,FALSE) -> 1988-07-01 | D22: 2026.01.17 | E22: 参加二十届四中全会精神教育集中培训《“十五五”时期经济社会发展的指导思想、重大原则和根本保证》《“十五五”时期经济社会发展的重大战略任务》，围绕深入贯彻落实党的二十届四中全会精神及省委十三届八次全会部署、深入贯彻落实市委十四届八次全会及县委十七届九次全会部署开展研讨 | F22: 6 | G22: =SUM(F22:F28) -> 20.5
D23: 2026.02.06 | E23: 参加2026年第一期“龙江先锋网”省级直播授课培训《提升基层安全应急能力 助力地方高质量发展》 | F23: 2.5
D24: 2026.02.26 | E24: 参加2026年第二期“龙江先锋网”省级直播授课培训《全面贯彻省委经济工作会议精神 确保实现‘十五五’开好局起好步》 | F24: 2.5
D25: 2026.3.20 | E25: 3月份党员大会 | F25: 2
D26: 2026.03.18 | E26: 参加2026年第一期“三江党旗红 党员在行动”直播授课培训《佳木斯市大垄密植增产技术措施》《狮头鹅和湖羊养殖实操精要与疫病防控》 | F26: 2.5
D27: 2026.03.25 | E27: 参加2026年第三期“龙江先锋网”省级直播授课培训《树立和践行正确政绩观》《大豆产业提质增效》 | F27: 2.5
D28: 2026.04.15 | E28: 参加2026年第五期“龙江先锋网”省级直播授课培训《深入学习贯彻习近平法治思想，以全民普法夯实基层治理法治根基》 | F28: 2.5
A29: 5 | B29: 邬峰 | C29: =VLOOKUP(B29,[1]导出名册!$A$1:$H$65536,8,FALSE) -> 1996-07-15 | D29: 2026.01.17 | E29: 参加二十届四中全会精神教育集中培训《“十五五”时期经济社会发展的指导思想、重大原则和根本保证》《“十五五”时期经济社会发展的重大战略任务》，围绕深入贯彻落实党的二十届四中全会精神及省委十三届八次全会部署、深入贯彻落实市委十四届八次全会及县委十七届九次全会部署开展研讨 | F29: 6 | G29: =SUM(F29:F34) -> 18.5
D30: 2026.02.06 | E30: 参加2026年第一期“龙江先锋网”省级直播授课培训《提升基层安全应急能力 助力地方高质量发展》 | F30: 2.5
D31: 2026.02.26 | E31: 参加2026年第二期“龙江先锋网”省级直播授课培训《全面贯彻省委经济工作会议精神 确保实现‘十五五’开好局起好步》 | F31: 2.5
D32: 2026.03.18 | E32: 参加2026年第一期“三江党旗红 党员在行动”直播授课培训《佳木斯市大垄密植增产技术措施》《狮头鹅和湖羊养殖实操精要与疫病防控》 | F32: 2.5
D33: 2026.03.25 | E33: 参加2026年第三期“龙江先锋网”省级直播授课培训《树立和践行正确政绩观》《大豆产业提质增效》 | F33: 2.5
D34: 2026.04.15 | E34: 参加2026年第五期“龙江先锋网”省级直播授课培训《深入学习贯彻习近平法治思想，以全民普法夯实基层治理法治根基》 | F34: 2.5
A35: 6 | B35: 姜士民 | C35: =VLOOKUP(B35,[1]导出名册!$A$1:$H$65536,8,FALSE) -> 1991-07-15 | D35: 2026.01.17 | E35: 参加二十届四中全会精神教育集中培训《“十五五”时期经济社会发展的指导思想、重大原则和根本保证》《“十五五”时期经济社会发展的重大战略任务》，围绕深入贯彻落实党的二十届四中全会精神及省委十三届八次全会部署、深入贯彻落实市委十四届八次全会及县委十七届九次全会部署开展研讨 | F35: 6 | G35: =SUM(F35:F40) -> 18.5
D36: 2026.02.06 | E36: 参加2026年第一期“龙江先锋网”省级直播授课培训《提升基层安全应急能力 助力地方高质量发展》 | F36: 2.5
D37: 2026.02.26 | E37: 参加2026年第二期“龙江先锋网”省级直播授课培训《全面贯彻省委经济工作会议精神 确保实现‘十五五’开好局起好步》 | F37: 2.5
D38: 2026.03.18 | E38: 参加2026年第一期“三江党旗红 党员在行动”直播授课培训《佳木斯市大垄密植增产技术措施》《狮头鹅和湖羊养殖实操精要与疫病防控》 | F38: 2.5
D39: 2026.03.25 | E39: 参加2026年第三期“龙江先锋网”省级直播授课培训《树立和践行正确政绩观》《大豆产业提质增效》 | F39: 2.5
D40: 2026.04.15 | E40: 参加2026年第五期“龙江先锋网”省级直播授课培训《深入学习贯彻习近平法治思想，以全民普法夯实基层治理法治根基》 | F40: 2.5
...
